Workbook

Sheet 분류
A1: 번호 | B1: 카테고리 | C1: 세부 카테고리 | D1: 질문 | E1: 정답 | F1: AnswerKind | G1: 확신 | H1: 난이도 | I1: 난이도 근거 | J1: storyID | K1: 마디 번호 | L1: 마디 이름 | M1: orderInChapter | N1: 구성
A2: 1 | B2: 역사 | C2: 고조선 | D2: 고조선의 건국이념은 무엇입니까? | E2: 홍익인간 | F2: heritage | G2: 낮음 | H2: 하 | I2: 질문 짧음(17자) · 정답 외우기 쉬움 | J2: time | K2: 1 | L2: 나라가 처음 열리다 | M2: 1 | N2: 쉬움
A3: 2 | B3: 역사 | C3: 고조선 | D3: 한국의 최초 국가 이름은 무엇입니까? | E3: 고조선 | F3: place | G3: 높음 | H3: 하 | I3: 질문 짧음(20자) · 정답 외우기 쉬움 | J3: time | K3: 1 | L3: 나라가 처음 열리다 | M3: 2 | N3: 쉬움
A4: 3 | B4: 역사 | C4: 고조선 | D4: 우리 나라에 최초의 국가인 고조선을 세운 사람은 누구입니까? | E4: 단군왕검 | F4: person | G4: 높음 | H4: 하 | I4: 질문 짧음(33자) · 정답 외우기 쉬움 | J4: time | K4: 1 | L4: 나라가 처음 열리다 | M4: 3 | N4: 쉬움
A5: 4 | B5: 역사 | C5: 고조선 | D5: 도읍지를 아사달로 삼아 고조선을 세운 왕(시조)는 누구입니까? | E5: 단군왕검 | F5: person | G5: 높음 | H5: 하 | I5: 질문 짧음(34자) · 정답 외우기 쉬움 | J5: time | K5: 1 | L5: 나라가 처음 열리다 | M5: 4 | N5: 쉬움
A6: 5 | B6: 역사 | C6: 고조선 | D6: 고조선의 건국이념인 홍익인간의 뜻은 무엇입니까? | E6: 널리 인간을 이롭게 한다. | F6: meaning | G6: 높음 | H6: 중 | I6: 질문 짧음(26자) · 정답 외우기 어려움 | J6: time | K6: 1 | L6: 나라가 처음 열리다 | M6: 5 | N6: 어려움
A7: 6 | B7: 역사 | C7: 고조선 | D7: 단군신화를 전하는 민족의 시조 단군의 기록은 어디에 담겨있는가? | E7: 삼국유사 | F7: heritage | G7: 보통 | H7: 하 | I7: 질문 짧음(35자) · 정답 외우기 쉬움 | J7: time | K7: 1 | L7: 나라가 처음 열리다 | M7: 6 | N7: 쉬움
A8: 7 | B8: 역사 | C8: 고조선 | D8: 널리 인간을 이롭게 한다는 뜻을 가진 고조선의 건국이념은 무엇입니까? | E8: 홍익인간 | F8: heritage | G8: 낮음 | H8: 하 | I8: 질문 보통(38자) · 정답 외우기 쉬움 | J8: time | K8: 1 | L8: 나라가 처음 열리다 | M8: 7 | N8: 쉬움
A9: 8 | B9: 역사 | C9: 고조선 | D9: 민족의 시조 단군에 관한 신화로 ‘삼국유사’를 통해 전해지는 신화는 무엇입니까? | E9: 단군신화 | F9: heritage | G9: 보통 | H9: 하 | I9: 질문 보통(44자) · 정답 외우기 쉬움 | J9: time | K9: 1 | L9: 나라가 처음 열리다 | M9: 8 | N9: 쉬움
A10: 9 | B10: 역사 | C10: 고조선 | D10: 우리나라 역사상 최초의 국가로 기원전 2333년 10월 3일에 세워진 나라의 이름은 무엇입니까? | E10: 고조선 | F10: place | G10: 높음 | H10: 하 | I10: 질문 보통(53자) · 정답 외우기 쉬움 | J10: time | K10: 1 | L10: 나라가 처음 열리다 | M10: 9 | N10: 쉬움
A11: 10 | B11: 역사 | C11: 고조선 | D11: 천제인 환인의 손자이며, 환웅의 아들로 서기전 2333년 아사달에 도읍을 정한 고조선을 세운 사람은 누구입니까? | E11: 단군왕검 | F11: person | G11: 높음 | H11: 중 | I11: 질문 김(62자) · 정답 외우기 쉬움 | J11: time | K11: 1 | L11: 나라가 처음 열리다 | M11: 10 | N11: 어려움
A12: 11 | B12: 역사 | C12: 고조선 | D12: 단군의 출생과 고조선에 대한 신화로 곰이 쑥과 마늘을 먹고 사람이 되어 환웅과 결혼을 해서 아들 낳았다는 이야기의 신화는 무엇입니까? | E12: 단군신화 | F12: heritage | G12: 보통 | H12: 중 | I12: 질문 김(74자) · 정답 외우기 쉬움 | J12: time | K12: 1 | L12: 나라가 처음 열리다 | M12: 11 | N12: 어려움
A13: 12 | B13: 역사 | C13: 고조선 | D13: 아사달에 도읍을 정하고 우리나라에 최초의 고조선이라는 나라를 세웠으며, 우리 민족의 시조로서 천제인 환인의 손자이며 환웅의 아들인 이 사람 누구입니까? | E13: 단군왕검 | F13: person | G13: 높음 | H13: 중 | I13: 질문 김(84자) · 정답 외우기 쉬움 | J13: time | K13: 1 | L13: 나라가 처음 열리다 | M13: 12 | N13: 어려움
... A1131: 1130 | B1131: 전통문화 | C1131: 전통 의상 | D1131: 직선과 약간의 곡선이 조화를 이루어 아름다운 우리나라 고유의 의복은 무엇입니까? | E1131: 한복 | F1131: thing | G1131: 높음 | H1131: 하 | I1131: 질문 보통(44자) · 정답 외우기 쉬움 | J1131: year | K1131: 7 | L1131: 입는 옷 | M1131: 1 | N1131: 쉬움

Sheet 이야기
A1: storyID | B1: 줄기 | C1: 마디 번호 | D1: 마디 이름 | E1: 문항 수 | F1: 쉬움 | G1: 어려움 | H1: 쉬움 비율
A2: time | B2: 시간 이야기 | C2: 1 | D2: 나라가 처음 열리다 | E2: =COUNTIFS(분류!$J$2:$J$1131,A2,분류!$L$2:$L$1131,D2) -> 12 | F2: =COUNTIFS(분류!$J$2:$J$1131,A2,분류!$L$2:$L$1131,D2,분류!$N$2:$N$1131,"쉬움") -> 8 | G2: =COUNTIFS(분류!$J$2:$J$1131,A2,분류!$L$2:$L$1131,D2,분류!$N$2:$N$1131,"어려움") -> 4 | H2: =IF(E2=0,"",F2/E2) -> 0.66666667
A3: time | B3: 시간 이야기 | C3: 2 | D3: 세 나라가 겨루다 | E3: =COUNTIFS(분류!$J$2:$J$1131,A3,분류!$L$2:$L$1131,D3) -> 30 | F3: =COUNTIFS(분류!$J$2:$J$1131,A3,분류!$L$2:$L$1131,D3,분류!$N$2:$N$1131,"쉬움") -> 20 | G3: =COUNTIFS(분류!$J$2:$J$1131,A3,분류!$L$2:$L$1131,D3,분류!$N$2:$N$1131,"어려움") -> 10 | H3: =IF(E3=0,"",F3/E3) -> 0.66666667
A4: time | B4: 시간 이야기 | C4: 3 | D4: 하나로 합쳐지다 | E4: =COUNTIFS(분류!$J$2:$J$1131,A4,분류!$L$2:$L$1131,D4) -> 15 | F4: =COUNTIFS(분류!$J$2:$J$1131,A4,분류!$L$2:$L$1131,D4,분류!$N$2:$N$1131,"쉬움") -> 10 | G4: =COUNTIFS(분류!$J$2:$J$1131,A4,분류!$L$2:$L$1131,D4,분류!$N$2:$N$1131,"어려움") -> 5 | H4: =IF(E4=0,"",F4/E4) -> 0.66666667
A5: time | B5: 시간 이야기 | C5: 4 | D5: 다시 갈라지다 | E5: =COUNTIFS(분류!$J$2:$J$1131,A5,분류!$L$2:$L$1131,D5) -> 2 | F5: =COUNTIFS(분류!$J$2:$J$1131,A5,분류!$L$2:$L$1131,D5,분류!$N$2:$N$1131,"쉬움") -> 2 | G5: =COUNTIFS(분류!$J$2:$J$1131,A5,분류!$L$2:$L$1131,D5,분류!$N$2:$N$1131,"어려움") -> 0 | H5: =IF(E5=0,"",F5/E5) -> 1
A6: time | B6: 시간 이야기 | C6: 5 | D6: 고려가 서다 | E6: =COUNTIFS(분류!$J$2:$J$1131,A6,분류!$L$2:$L$1131,D6) -> 15 | F6: =COUNTIFS(분류!$J$2:$J$1131,A6,분류!$L$2:$L$1131,D6,분류!$N$2:$N$1131,"쉬움") -> 12 | G6: =COUNTIFS(분류!$J$2:$J$1131,A6,분류!$L$2:$L$1131,D6,분류!$N$2:$N$1131,"어려움") -> 3 | H6: =IF(E6=0,"",F6/E6) -> 0.8
A7: time | B7: 시간 이야기 | C7: 6 | D7: 조선 오백 년 | E7: =COUNTIFS(분류!$J$2:$J$1131,A7,분류!$L$2:$L$1131,D7) -> 55 | F7: =COUNTIFS(분류!$J$2:$J$1131,A7,분류!$L$2:$L$1131,D7,분류!$N$2:$N$1131,"쉬움") -> 35 | G7: =COUNTIFS(분류!$J$2:$J$1131,A7,분류!$L$2:$L$1131,D7,분류!$N$2:$N$1131,"어려움") -> 20 | H7: =IF(E7=0,"",F7/E7) -> 0.63636364
A8: time | B8: 시간 이야기 | C8: 7 | D8: 나라를 빼앗기다 | E8: =COUNTIFS(분류!$J$2:$J$1131,A8,분류!$L$2:$L$1131,D8) -> 28 | F8: =COUNTIFS(분류!$J$2:$J$1131,A8,분류!$L$2:$L$1131,D8,분류!$N$2:$N$1131,"쉬움") -> 8 | G8: =COUNTIFS(분류!$J$2:$J$1131,A8,분류!$L$2:$L$1131,D8,분류!$N$2:$N$1131,"어려움") -> 20 | H8: =IF(E8=0,"",F8/E8) -> 0.28571429
A9: time | B9: 시간 이야기 | C9: 8 | D9: 전쟁과 갈라진 땅 | E9: =COUNTIFS(분류!$J$2:$J$1131,A9,분류!$L$2:$L$1131,D9) -> 18 | F9: =COUNTIFS(분류!$J$2:$J$1131,A9,분류!$L$2:$L$1131,D9,분류!$N$2:$N$1131,"쉬움") -> 3 | G9: =COUNTIFS(분류!$J$2:$J$1131,A9,분류!$L$2:$L$1131,D9,분류!$N$2:$N$1131,"어려움") -> 15 | H9: =IF(E9=0,"",F9/E9) -> 0.16666667
A10: time | B10: 시간 이야기 | C10: 9 | D10: 전체를 훑어보기 | E10: =COUNTIFS(분류!$J$2:$J$1131,A10,분류!$L$2:$L$1131,D10) -> 1 | F10: =COUNTIFS(분류!$J$2:$J$1131,A10,분류!$L$2:$L$1131,D10,분류!$N$2:$N$1131,"쉬움") -> 0 | G10: =COUNTIFS(분류!$J$2:$J$1131,A10,분류!$L$2:$L$1131,D10,분류!$N$2:$N$1131,"어려움") -> 1 | H10: =IF(E10=0,"",F10/E10) -> 0
A11: time | B11: 시간 이야기 | C11: 10 | D11: 남아 있는 것들 | E11: =COUNTIFS(분류!$J$2:$J$1131,A11,분류!$L$2:$L$1131,D11) -> 18 | F11: =COUNTIFS(분류!$J$2:$J$1131,A11,분류!$L$2:$L$1131,D11,분류!$N$2:$N$1131,"쉬움") -> 10 | G11: =COUNTIFS(분류!$J$2:$J$1131,A11,분류!$L$2:$L$1131,D11,분류!$N$2:$N$1131,"어려움") -> 8 | H11: =IF(E11=0,"",F11/E11) -> 0.55555556
A12: time | B12: 시간 이야기 | C12: 11 | D12: 세계가 아는 것들 | E12: =COUNTIFS(분류!$J$2:$J$1131,A12,분류!$L$2:$L$1131,D12) -> 21 | F12: =COUNTIFS(분류!$J$2:$J$1131,A12,분류!$L$2:$L$1131,D12,분류!$N$2:$N$1131,"쉬움") -> 8 | G12: =COUNTIFS(분류!$J$2:$J$1131,A12,분류!$L$2:$L$1131,D12,분류!$N$2:$N$1131,"어려움") -> 13 | H12: =IF(E12=0,"",F12/E12) -> 0.38095238
A13: life | B13: 살아가는 이야기 | C13: 1 | D13: 가족이 되다 | E13: =COUNTIFS(분류!$J$2:$J$1131,A13,분류!$L$2:$L$1131,D13) -> 18 | F13: =COUNTIFS(분류!$J$2:$J$1131,A13,분류!$L$2:$L$1131,D13,분류!$N$2:$N$1131,"쉬움") -> 14 | G13: =COUNTIFS(분류!$J$2:$J$1131,A13,분류!$L$2:$L$1131,D13,분류!$N$2:$N$1131,"어려움") -> 4 | H13: =IF(E13=0,"",F13/E13) -> 0.77777778
... A48: year | B48: 한 해의 이야기 | C48: 7 | D48: 입는 옷 | E48: =COUNTIFS(분류!$J$2:$J$1131,A48,분류!$L$2:$L$1131,D48) -> 1 | F48: =COUNTIFS(분류!$J$2:$J$1131,A48,분류!$L$2:$L$1131,D48,분류!$N$2:$N$1131,"쉬움") -> 1 | G48: =COUNTIFS(분류!$J$2:$J$1131,A48,분류!$L$2:$L$1131,D48,분류!$N$2:$N$1131,"어려움") -> 0 | H48: =IF(E48=0,"",F48/E48) -> 1
A49: 합계 | E49: =SUM(E2:E48) -> 1130 | F49: =SUM(F2:F48) -> 553 | G49: =SUM(G2:G48) -> 577 | H49: =F49/E49 -> 0.48938053

Sheet 요약
A1: AnswerKind | B1: 뜻 | C1: 문항 수 | D1: 하 | E1: 중 | F1: 상
A2: meaning | B2: 뜻풀이 (답이 설명 문장) | C2: =COUNTIF(분류!$F$2:$F$1131,A2) -> 174 | D2: =COUNTIFS(분류!$F$2:$F$1131,$A2,분류!$H$2:$H$1131,"하") -> 0 | E2: =COUNTIFS(분류!$F$2:$F$1131,$A2,분류!$H$2:$H$1131,"중") -> 165 | F2: =COUNTIFS(분류!$F$2:$F$1131,$A2,분류!$H$2:$H$1131,"상") -> 9
A3: list | B3: 여러 항목 | C3: =COUNTIF(분류!$F$2:$F$1131,A3) -> 45 | D3: =COUNTIFS(분류!$F$2:$F$1131,$A3,분류!$H$2:$H$1131,"하") -> 0 | E3: =COUNTIFS(분류!$F$2:$F$1131,$A3,분류!$H$2:$H$1131,"중") -> 44 | F3: =COUNTIFS(분류!$F$2:$F$1131,$A3,분류!$H$2:$H$1131,"상") -> 1
A4: number | B4: 연도·날짜·숫자 | C4: =COUNTIF(분류!$F$2:$F$1131,A4) -> 30 | D4: =COUNTIFS(분류!$F$2:$F$1131,$A4,분류!$H$2:$H$1131,"하") -> 0 | E4: =COUNTIFS(분류!$F$2:$F$1131,$A4,분류!$H$2:$H$1131,"중") -> 24 | F4: =COUNTIFS(분류!$F$2:$F$1131,$A4,분류!$H$2:$H$1131,"상") -> 6
A5: person | B5: 사람 | C5: =COUNTIF(분류!$F$2:$F$1131,A5) -> 71 | D5: =COUNTIFS(분류!$F$2:$F$1131,$A5,분류!$H$2:$H$1131,"하") -> 57 | E5: =COUNTIFS(분류!$F$2:$F$1131,$A5,분류!$H$2:$H$1131,"중") -> 14 | F5: =COUNTIFS(분류!$F$2:$F$1131,$A5,분류!$H$2:$H$1131,"상") -> 0
A6: place | B6: 나라와 땅 | C6: =COUNTIF(분류!$F$2:$F$1131,A6) -> 74 | D6: =COUNTIFS(분류!$F$2:$F$1131,$A6,분류!$H$2:$H$1131,"하") -> 60 | E6: =COUNTIFS(분류!$F$2:$F$1131,$A6,분류!$H$2:$H$1131,"중") -> 14 | F6: =COUNTIFS(분류!$F$2:$F$1131,$A6,분류!$H$2:$H$1131,"상") -> 0
A7: day | B7: 기념일·명절 | C7: =COUNTIF(분류!$F$2:$F$1131,A7) -> 10 | D7: =COUNTIFS(분류!$F$2:$F$1131,$A7,분류!$H$2:$H$1131,"하") -> 3 | E7: =COUNTIFS(분류!$F$2:$F$1131,$A7,분류!$H$2:$H$1131,"중") -> 7 | F7: =COUNTIFS(분류!$F$2:$F$1131,$A7,분류!$H$2:$H$1131,"상") -> 0
A8: event | B8: 사건·전쟁 | C8: =COUNTIF(분류!$F$2:$F$1131,A8) -> 27 | D8: =COUNTIFS(분류!$F$2:$F$1131,$A8,분류!$H$2:$H$1131,"하") -> 17 | E8: =COUNTIFS(분류!$F$2:$F$1131,$A8,분류!$H$2:$H$1131,"중") -> 10 | F8: =COUNTIFS(분류!$F$2:$F$1131,$A8,분류!$H$2:$H$1131,"상") -> 0
A9: thing | B9: 물건·음식·옷·놀이·상징 | C9: =COUNTIF(분류!$F$2:$F$1131,A9) -> 106 | D9: =COUNTIFS(분류!$F$2:$F$1131,$A9,분류!$H$2:$H$1131,"하") -> 57 | E9: =COUNTIFS(분류!$F$2:$F$1131,$A9,분류!$H$2:$H$1131,"중") -> 49 | F9: =COUNTIFS(분류!$F$2:$F$1131,$A9,분류!$H$2:$H$1131,"상") -> 0
A10: heritage | B10: 문화유산·책·옛이야기 | C10: =COUNTIF(분류!$F$2:$F$1131,A10) -> 60 | D10: =COUNTIFS(분류!$F$2:$F$1131,$A10,분류!$H$2:$H$1131,"하") -> 40 | E10: =COUNTIFS(분류!$F$2:$F$1131,$A10,분류!$H$2:$H$1131,"중") -> 19 | F10: =COUNTIFS(분류!$F$2:$F$1131,$A10,분류!$H$2:$H$1131,"상") -> 1
A11: system | B11: 제도·기관·권리 | C11: =COUNTIF(분류!$F$2:$F$1131,A11) -> 379 | D11: =COUNTIFS(분류!$F$2:$F$1131,$A11,분류!$H$2:$H$1131,"하") -> 226 | E11: =COUNTIFS(분류!$F$2:$F$1131,$A11,분류!$H$2:$H$1131,"중") -> 153 | F11: =COUNTIFS(분류!$F$2:$F$1131,$A11,분류!$H$2:$H$1131,"상") -> 0
A12: procedure | B12: 생활 절차·서류·호칭 | C12: =COUNTIF(분류!$F$2:$F$1131,A12) -> 154 | D12: =COUNTIFS(분류!$F$2:$F$1131,$A12,분류!$H$2:$H$1131,"하") -> 93 | E12: =COUNTIFS(분류!$F$2:$F$1131,$A12,분류!$H$2:$H$1131,"중") -> 61 | F12: =COUNTIFS(분류!$F$2:$F$1131,$A12,분류!$H$2:$H$1131,"상") -> 0
A13: 합계 | C13: =SUM(C2:C12) -> 1130 | D13: =SUM(D2:D12) -> 553 | E13: =SUM(E2:E12) -> 560 | F13: =SUM(F2:F12) -> 17
A15: 난이도 규칙 (70세 기준)
A16: 질문 길이 | B16: 35자 이하 0점 · 36~60자 1점 · 61자 이상 2점
A17: 정답 부담 | B17: 5자 이하 낱말 0점 · 조금 김 1점 · 길거나 여럿이거나 뜻풀이·숫자 2점
A18: 합계 | B18: 0~1점 하 · 2~3점 중 · 4점 상
A20: 마디 안 순서 | B20: 쉬움 4 : 어려움 1 로 번갈아. 어디까지 풀든 8:2가 유지됩니다.
A22: 확신 높음 | B22: 정답 자체가 목록에 있거나 모양이 분명함
A23: 확신 보통 | B23: 카테고리와 낱말로 미루어 정함
A24: 확신 낮음 | B24: 근거가 약함 — 노란 줄. 눈으로 확인 필요
A26: 이번에 고친 것
A27: · 뺀 칸 | B27: 「문제 유형」과 「난이도(원본)」을 지웠습니다
A28: · 빈 카테고리 | B28: 132줄 중 정답이 있는 23줄을 내용으로 채웠습니다 (대부분 유네스코 유산·사법부)
A29: · 세부 이름 | B29: 「전통음식→전통 음식」「정통 의상→전통 의상」「전통 가옥(집)→전통 가옥」「한국전쟁(6.25)→한국전쟁」「전통 문화→전통 예술」
A30: · 「일반」 12줄 | B30: 화폐·지리·주변국가·시대 순서로 옮겼습니다
A31: · 복지제도 | B31: 「법」에서 「제도와 생활」로 옮겼습니다
A32: · 정답 없는 문항 | B32: 120줄을 「정답 없음」 시트로 옮겼습니다 — 문제로 낼 수 없습니다
A34: 만든 방법 | B34: AnswerKind·난이도·이야기 배치 모두 규칙으로 자동 부여했습니다. 사람이 하나씩 매긴 것이 아닙니다.
A35: 출처 | B35: 귀화 문제집 20250518.numbers

Sheet 정답 없음
A1: 원래 번호 | B1: 카테고리 | C1: 세부 카테고리 | D1: 질문
A2: 110 | B2: 역사 | C2: 조선시대 | D2: 대동여지도를 만든 사람은 누구입니까?
A3: 120 | B3: 역사 | C3: 조선시대 | D3: 홍길동전을 만든 사람은 누구입니까?
A4: 166 | B4: 역사 | C4: 일제강점기 | D4: 한인애국단 소속으로 일본에서 일왕을 시해하려다 실패한 인물은 누구입니까?
A5: 167 | B5: 역사 | C5: 일제강점기 | D5: 말이 다치고 궁내대신의 마차가 뒤집어 졌으나 히로히토는 다치지 않아 거사는 실패로 돌아갔습니다. 그 사람은 누구입니까?
A6: 174 | B6: 역사 | C6: 한국전쟁 | D6: 한국이 분단된 결정적인 이유는 무엇입니까?
A7: 176 | B7: 역사 | C7: 한국전쟁 | D7: 6.25 전쟁의 자료를 보존하고 추모하기 위해 만들어진 곳은 어디입니까?
A8: 180 | B8: 역사 | C8: 한국전쟁 | D8: 38선과 휴전선은 어떻게 다른가요?
A9: 250 | B9: 대한민국 | C9: 지리 | D9: 남부대륙에 있는 큰 산으로 세 개의 도(전라남도, 전라북도, 경상남도)에 걸쳐 있는 두 번째로 높은 산은?
A10: 347 | B10: 정치 | C10: 행정부 | D10: 대통령의 집무실 청와대는 서울 어디에 있습니까?
A11: 485 | B11: 정치 | C11: 민주주의 | D11: 자신의 정치적인 의도를 밝히는 촛불 집회 사위 등과 같이 개인이 자유로운 자신의 의견을 주장할 수 있는 것은 헌번의 어떤 기본원리 때문입니까?
A12: 738 | B12: 제도와 생활 | C12: 제도 | D12: 국가에서 지원하는 국가 복지서비스(바우처)를 한 장의 카드로 이용할 수 있는 카드는 어떤 카드입니까?
A13: 1135 | D13: 현재 국무총리는 누구입니까?
A14: 1136 | D14: 1936년 베를린 올림픽 마라톤에서 금메달을 수상한 사람은 누구입니까?
A15: 1137 | D15: 대학에 가는 공부를 하는 곳은?
A16: 1141 | D16: 일제강점기 시절에 과학으로 민족의 힘을 키우고자 했던 과학자는 누구입니까?
A17: 1142 | D17: 북한 핵실험과 장거리 미사일 발사를 계기로 한반도에 배치가 이루어진 고고도 미사일 방어 체계를 무엇이라고 합니까?
A18: 1143 | D18: 일제시대 때 우리나라의 독립을 위해 몸을 바쳐 일본과 싸운 것을 무슨 운동이라고 합니까?
A19: 1144 | D19: 다음 대통령 선거는 언제입니까?
A20: 1145 | D20: 다음 국회의원 선거는 언제입니까?
A21: 1146 | D21: 다음 주민대표 선거는 언제입니까?
A22: 1151 | D22: 한국에서 90일 이상 거주하려는 외국인이 한국에 들어오면 출입국관리 사무소에서 발급하는 것은 무엇입니까?
A23: 1152 | D23: 태어나면서부터 가지게 되는 인간으로서 당연히 보호 받아야할 권리를 무엇이라고 합니까?
A24: 1153 | D24: 법원 이외에 권리를 침해 당했을 때 권리를 보호받을 수 있는 기관에는 어떤 것들이 있습니까?
... A51: 1180 | D51: 조선시대의 궁궐 중 하나로 아름다운 정원인 비원을 가지고 있는 곳은 어디입니까?
A52: 1181 | B52: 문화유산 | C52: 유네스코 유산 | D52: 조선의 왕조의 유교적 전통인 왕실의 제례 문화를 보여주는 문화 유산으로, 유네스코 세계문화 유산으로 지정된 곳은 어디입니까?
A53: 1182 | D53: 조선 정조 때 정약용의 거중기를 이용하여 경기도에 쌓은 성의 이름은 무엇입니까?
A54: 1183 | D54: 줄 위에서 노래, 춤, 곡예를 하며 재미있게 얘기하는 전통 예술은 무엇입니까?
A55: 1184 | D55: 조선을 대표하는 학자 중 한명으로서 중국이나 일본까지도 이름이 알려졌던 인물로 고향에서 제자를 교육하고 학문을 연구하는데 인생을 바친 사람은 누구입니까?
A56: 1185 | D56: 자신의 학문을 통해 사회를 개혁하기 위해 많은 노력을 하였으며, 일본의 침략을 막고자 미리 10만명의 군대를 양성해야 한다고 주장했던 것으로 유명한 사람은 누구입니까?
A57: 1186 | D57: 1세대가 하나의 건축물 안에서 독립된 주거생활을 할 수 있는 구조로 된 주택을 뭐라고 하나요?
A58: 1187 | D58: 한 가문의 계통과 혈통 관계를 적어 기록한 것을 뭐라고 하나요?
A59: 1188 | D59: 고조선에서 남에게 상처를 입힌 자는 곡식으로 갚아야 한다는 법은 어떤 법입니까?
A60: 1189 | D60: 대한민국의 광복을 위해 자신의 목숨을 바친 독립 운동가 세명 이상을 말해보세요.
A61: 1190 | D61: 상주를 위문하는 것
A62: 1191 | D62: 제도여도 답이 제도가 붙지 않는 것들이 있다.
A63: 1192 | D63: 만든이의 권리를 보호하여 문화를 발전시키는 것을 목적으로 하는 것은 무엇입니까?
A64: 1193 | D64: 노동 삼권이 필요한 이유
... A85: 1214 | D85: 형사 피고인이라도 유죄의 판결이 확정될 때까지는 무죄로 추정된다는 법은 무엇입니까?
A86: 1215 | B86: 문화유산 | C86: 유네스코 유산 | D86: 문화유산 중 세계기록 유산에 등재되어 있는 것은?
...
